{
 "cells": [
  {
   "cell_type": "code",
   "execution_count": 1,
   "metadata": {},
   "outputs": [],
   "source": [
    "import pandas as pd\n",
    "import numpy as np\n",
    "import matplotlib.pyplot as plt\n",
    "import h5py\n",
    "import os"
   ]
  },
  {
   "cell_type": "code",
   "execution_count": 2,
   "metadata": {},
   "outputs": [],
   "source": [
    "data_nobatch_fp = '../../code/phenotyping/their-embeddings/data-nobatch.h5'"
   ]
  },
  {
   "cell_type": "code",
   "execution_count": 3,
   "metadata": {},
   "outputs": [
    {
     "data": {
      "text/plain": [
       "h5py._hl.files.File"
      ]
     },
     "execution_count": 3,
     "metadata": {},
     "output_type": "execute_result"
    }
   ],
   "source": [
    "f = h5py.File(data_nobatch_fp, 'r')\n",
    "type(f)"
   ]
  },
  {
   "cell_type": "code",
   "execution_count": 4,
   "metadata": {},
   "outputs": [
    {
     "data": {
      "text/plain": [
       "['test',\n",
       " 'test_id',\n",
       " 'test_label',\n",
       " 'test_subj',\n",
       " 'test_time',\n",
       " 'train',\n",
       " 'train_id',\n",
       " 'train_label',\n",
       " 'train_subj',\n",
       " 'train_time',\n",
       " 'val',\n",
       " 'val_id',\n",
       " 'val_label',\n",
       " 'val_subj',\n",
       " 'val_time',\n",
       " 'w2v']"
      ]
     },
     "execution_count": 4,
     "metadata": {},
     "output_type": "execute_result"
    }
   ],
   "source": [
    "list(f.keys())"
   ]
  },
  {
   "cell_type": "code",
   "execution_count": 5,
   "metadata": {},
   "outputs": [
    {
     "name": "stdout",
     "output_type": "stream",
     "text": [
      "Computing features.\n"
     ]
    },
    {
     "ename": "OSError",
     "evalue": "[Errno 22] Can't read data (file read failed: time = Mon Nov 14 22:56:39 2022\n, filename = '../../code/phenotyping/their-embeddings/data-nobatch.h5', file descriptor = 4, errno = 22, error message = 'Invalid argument', buf = 000002A1C750D040, total read size = 886527488, bytes this sub-read = 886527488, bytes actually read = 18446744073709551615, offset = 45915248)",
     "output_type": "error",
     "traceback": [
      "\u001b[1;31m---------------------------------------------------------------------------\u001b[0m",
      "\u001b[1;31mOSError\u001b[0m                                   Traceback (most recent call last)",
      "\u001b[1;32m~\\AppData\\Local\\Temp\\ipykernel_9780\\1339210407.py\u001b[0m in \u001b[0;36m<module>\u001b[1;34m\u001b[0m\n\u001b[0;32m      1\u001b[0m \u001b[1;32mwith\u001b[0m \u001b[0mh5py\u001b[0m\u001b[1;33m.\u001b[0m\u001b[0mFile\u001b[0m\u001b[1;33m(\u001b[0m\u001b[0mdata_nobatch_fp\u001b[0m\u001b[1;33m,\u001b[0m \u001b[1;34m\"r\"\u001b[0m\u001b[1;33m)\u001b[0m \u001b[1;32mas\u001b[0m \u001b[0mf\u001b[0m\u001b[1;33m:\u001b[0m\u001b[1;33m\u001b[0m\u001b[1;33m\u001b[0m\u001b[0m\n\u001b[0;32m      2\u001b[0m     \u001b[0mprint\u001b[0m\u001b[1;33m(\u001b[0m\u001b[1;34m'Computing features.'\u001b[0m\u001b[1;33m)\u001b[0m\u001b[1;33m\u001b[0m\u001b[1;33m\u001b[0m\u001b[0m\n\u001b[1;32m----> 3\u001b[1;33m     \u001b[0mtrain_x\u001b[0m \u001b[1;33m=\u001b[0m \u001b[0mf\u001b[0m\u001b[1;33m[\u001b[0m\u001b[1;34m\"train\"\u001b[0m\u001b[1;33m]\u001b[0m\u001b[1;33m[\u001b[0m\u001b[1;33m:\u001b[0m\u001b[1;33m]\u001b[0m\u001b[1;33m\u001b[0m\u001b[1;33m\u001b[0m\u001b[0m\n\u001b[0m\u001b[0;32m      4\u001b[0m     \u001b[0mvalid_x\u001b[0m \u001b[1;33m=\u001b[0m \u001b[0mf\u001b[0m\u001b[1;33m[\u001b[0m\u001b[1;34m\"val\"\u001b[0m\u001b[1;33m]\u001b[0m\u001b[1;33m[\u001b[0m\u001b[1;33m:\u001b[0m\u001b[1;33m]\u001b[0m\u001b[1;33m\u001b[0m\u001b[1;33m\u001b[0m\u001b[0m\n\u001b[0;32m      5\u001b[0m     \u001b[0mtest_x\u001b[0m \u001b[1;33m=\u001b[0m \u001b[0mf\u001b[0m\u001b[1;33m[\u001b[0m\u001b[1;34m\"test\"\u001b[0m\u001b[1;33m]\u001b[0m\u001b[1;33m[\u001b[0m\u001b[1;33m:\u001b[0m\u001b[1;33m]\u001b[0m\u001b[1;33m\u001b[0m\u001b[1;33m\u001b[0m\u001b[0m\n",
      "\u001b[1;32mh5py\\_objects.pyx\u001b[0m in \u001b[0;36mh5py._objects.with_phil.wrapper\u001b[1;34m()\u001b[0m\n",
      "\u001b[1;32mh5py\\_objects.pyx\u001b[0m in \u001b[0;36mh5py._objects.with_phil.wrapper\u001b[1;34m()\u001b[0m\n",
      "\u001b[1;32mc:\\Users\\colle\\anaconda3\\lib\\site-packages\\h5py\\_hl\\dataset.py\u001b[0m in \u001b[0;36m__getitem__\u001b[1;34m(self, args, new_dtype)\u001b[0m\n\u001b[0;32m    739\u001b[0m         \u001b[1;32mif\u001b[0m \u001b[0mself\u001b[0m\u001b[1;33m.\u001b[0m\u001b[0m_fast_read_ok\u001b[0m \u001b[1;32mand\u001b[0m \u001b[1;33m(\u001b[0m\u001b[0mnew_dtype\u001b[0m \u001b[1;32mis\u001b[0m \u001b[1;32mNone\u001b[0m\u001b[1;33m)\u001b[0m\u001b[1;33m:\u001b[0m\u001b[1;33m\u001b[0m\u001b[1;33m\u001b[0m\u001b[0m\n\u001b[0;32m    740\u001b[0m             \u001b[1;32mtry\u001b[0m\u001b[1;33m:\u001b[0m\u001b[1;33m\u001b[0m\u001b[1;33m\u001b[0m\u001b[0m\n\u001b[1;32m--> 741\u001b[1;33m                 \u001b[1;32mreturn\u001b[0m \u001b[0mself\u001b[0m\u001b[1;33m.\u001b[0m\u001b[0m_fast_reader\u001b[0m\u001b[1;33m.\u001b[0m\u001b[0mread\u001b[0m\u001b[1;33m(\u001b[0m\u001b[0margs\u001b[0m\u001b[1;33m)\u001b[0m\u001b[1;33m\u001b[0m\u001b[1;33m\u001b[0m\u001b[0m\n\u001b[0m\u001b[0;32m    742\u001b[0m             \u001b[1;32mexcept\u001b[0m \u001b[0mTypeError\u001b[0m\u001b[1;33m:\u001b[0m\u001b[1;33m\u001b[0m\u001b[1;33m\u001b[0m\u001b[0m\n\u001b[0;32m    743\u001b[0m                 \u001b[1;32mpass\u001b[0m  \u001b[1;31m# Fall back to Python read pathway below\u001b[0m\u001b[1;33m\u001b[0m\u001b[1;33m\u001b[0m\u001b[0m\n",
      "\u001b[1;32mh5py\\_selector.pyx\u001b[0m in \u001b[0;36mh5py._selector.Reader.read\u001b[1;34m()\u001b[0m\n",
      "\u001b[1;31mOSError\u001b[0m: [Errno 22] Can't read data (file read failed: time = Mon Nov 14 22:56:39 2022\n, filename = '../../code/phenotyping/their-embeddings/data-nobatch.h5', file descriptor = 4, errno = 22, error message = 'Invalid argument', buf = 000002A1C750D040, total read size = 886527488, bytes this sub-read = 886527488, bytes actually read = 18446744073709551615, offset = 45915248)"
     ]
    }
   ],
   "source": [
    "with h5py.File(data_nobatch_fp, \"r\") as f:\n",
    "    print('Computing features.')\n",
    "    train_x = f[\"train\"][:]\n",
    "    valid_x = f[\"val\"][:]\n",
    "    test_x = f[\"test\"][:]"
   ]
  },
  {
   "cell_type": "code",
   "execution_count": 6,
   "metadata": {},
   "outputs": [
    {
     "ename": "NameError",
     "evalue": "name 'train_x' is not defined",
     "output_type": "error",
     "traceback": [
      "\u001b[1;31m---------------------------------------------------------------------------\u001b[0m",
      "\u001b[1;31mNameError\u001b[0m                                 Traceback (most recent call last)",
      "\u001b[1;32m~\\AppData\\Local\\Temp\\ipykernel_9780\\1852434940.py\u001b[0m in \u001b[0;36m<module>\u001b[1;34m\u001b[0m\n\u001b[1;32m----> 1\u001b[1;33m \u001b[0mtype\u001b[0m\u001b[1;33m(\u001b[0m\u001b[0mtrain_x\u001b[0m\u001b[1;33m)\u001b[0m\u001b[1;33m\u001b[0m\u001b[1;33m\u001b[0m\u001b[0m\n\u001b[0m",
      "\u001b[1;31mNameError\u001b[0m: name 'train_x' is not defined"
     ]
    }
   ],
   "source": [
    "type(train_x)"
   ]
  },
  {
   "cell_type": "code",
   "execution_count": null,
   "metadata": {},
   "outputs": [],
   "source": [
    "conditions = ['cohort', #0\n",
    "              'Obesity', #1\n",
    "              'Non.Adherence', #2\n",
    "              'Developmental.Delay.Retardation', #3\n",
    "              'Advanced.Heart.Disease', #4\n",
    "              'Advanced.Lung.Disease', #5\n",
    "              'Schizophrenia.and.other.Psychiatric.Disorders', #6\n",
    "              'Alcohol.Abuse', #7\n",
    "              'Other.Substance.Abuse', #8\n",
    "              'Chronic.Pain.Fibromyalgia', #9\n",
    "              'Chronic.Neurological.Dystrophies', #10\n",
    "              'Advanced.Cancer', #11\n",
    "              'Depression', #12\n",
    "              'Dementia', #13\n",
    "              'Unsure'] #14\n"
   ]
  }
 ],
 "metadata": {
  "kernelspec": {
   "display_name": "Python 3.9.13 ('base')",
   "language": "python",
   "name": "python3"
  },
  "language_info": {
   "codemirror_mode": {
    "name": "ipython",
    "version": 3
   },
   "file_extension": ".py",
   "mimetype": "text/x-python",
   "name": "python",
   "nbconvert_exporter": "python",
   "pygments_lexer": "ipython3",
   "version": "3.9.13"
  },
  "orig_nbformat": 4,
  "vscode": {
   "interpreter": {
    "hash": "061a7383154eb359032e7cdb1e778fe469408ddcd916e8d99e0baa0b31a4319c"
   }
  }
 },
 "nbformat": 4,
 "nbformat_minor": 2
}
